2022-04-08 05:48:13,640 INFO: Takaici startup... [in C:\Users\kaunda\Desktop\EPL_MATCH_PREDICTOR20220413_V2\app\__init__.py:54]
2022-04-08 05:48:41,701 ERROR: Exception on /index [GET] [in c:\program files (x86)\python37-32\lib\site-packages\flask\app.py:1891]
Traceback (most recent call last):
  File "c:\program files (x86)\python37-32\lib\site-packages\sqlalchemy\engine\base.py", line 1249, in _execute_context
    cursor, statement, parameters, context
  File "c:\program files (x86)\python37-32\lib\site-packages\sqlalchemy\engine\default.py", line 552, in do_execute
    cursor.execute(statement, parameters)
  File "c:\program files (x86)\python37-32\lib\site-packages\pymysql\cursors.py", line 170, in execute
    result = self._query(query)
  File "c:\program files (x86)\python37-32\lib\site-packages\pymysql\cursors.py", line 328, in _query
    conn.query(q)
  File "c:\program files (x86)\python37-32\lib\site-packages\pymysql\connections.py", line 517, in query
    self._affected_rows = self._read_query_result(unbuffered=unbuffered)
  File "c:\program files (x86)\python37-32\lib\site-packages\pymysql\connections.py", line 732, in _read_query_result
    result.read()
  File "c:\program files (x86)\python37-32\lib\site-packages\pymysql\connections.py", line 1075, in read
    first_packet = self.connection._read_packet()
  File "c:\program files (x86)\python37-32\lib\site-packages\pymysql\connections.py", line 684, in _read_packet
    packet.check_error()
  File "c:\program files (x86)\python37-32\lib\site-packages\pymysql\protocol.py", line 220, in check_error
    err.raise_mysql_exception(self._data)
  File "c:\program files (x86)\python37-32\lib\site-packages\pymysql\err.py", line 109, in raise_mysql_exception
    raise errorclass(errno, errval)
pymysql.err.ProgrammingError: (1146, "Table 'epl_predictor.prediction_view' doesn't exist")

The above exception was the direct cause of the following exception:

Traceback (most recent call last):
  File "c:\program files (x86)\python37-32\lib\site-packages\flask\app.py", line 2446, in wsgi_app
    response = self.full_dispatch_request()
  File "c:\program files (x86)\python37-32\lib\site-packages\flask\app.py", line 1951, in full_dispatch_request
    rv = self.handle_user_exception(e)
  File "c:\program files (x86)\python37-32\lib\site-packages\flask\app.py", line 1820, in handle_user_exception
    reraise(exc_type, exc_value, tb)
  File "c:\program files (x86)\python37-32\lib\site-packages\flask\_compat.py", line 39, in reraise
    raise value
  File "c:\program files (x86)\python37-32\lib\site-packages\flask\app.py", line 1949, in full_dispatch_request
    rv = self.dispatch_request()
  File "c:\program files (x86)\python37-32\lib\site-packages\flask\app.py", line 1935, in dispatch_request
    return self.view_functions[rule.endpoint](**req.view_args)
  File "c:\program files (x86)\python37-32\lib\site-packages\flask_login\utils.py", line 261, in decorated_view
    return func(*args, **kwargs)
  File "C:\Users\kaunda\Desktop\EPL_MATCH_PREDICTOR20220413_V2\app\routes.py", line 27, in index
    predictions = PredictionView.query.filter_by(user_id = user.id).order_by(PredictionView.prediction_date.desc()).paginate(page,app.config['DOCUMENTS_PER_PAGE'], False)
  File "c:\program files (x86)\python37-32\lib\site-packages\flask_sqlalchemy\__init__.py", line 496, in paginate
    items = self.limit(per_page).offset((page - 1) * per_page).all()
  File "c:\program files (x86)\python37-32\lib\site-packages\sqlalchemy\orm\query.py", line 3178, in all
    return list(self)
  File "c:\program files (x86)\python37-32\lib\site-packages\sqlalchemy\orm\query.py", line 3334, in __iter__
    return self._execute_and_instances(context)
  File "c:\program files (x86)\python37-32\lib\site-packages\sqlalchemy\orm\query.py", line 3359, in _execute_and_instances
    result = conn.execute(querycontext.statement, self._params)
  File "c:\program files (x86)\python37-32\lib\site-packages\sqlalchemy\engine\base.py", line 988, in execute
    return meth(self, multiparams, params)
  File "c:\program files (x86)\python37-32\lib\site-packages\sqlalchemy\sql\elements.py", line 287, in _execute_on_connection
    return connection._execute_clauseelement(self, multiparams, params)
  File "c:\program files (x86)\python37-32\lib\site-packages\sqlalchemy\engine\base.py", line 1107, in _execute_clauseelement
    distilled_params,
  File "c:\program files (x86)\python37-32\lib\site-packages\sqlalchemy\engine\base.py", line 1253, in _execute_context
    e, statement, parameters, cursor, context
  File "c:\program files (x86)\python37-32\lib\site-packages\sqlalchemy\engine\base.py", line 1473, in _handle_dbapi_exception
    util.raise_from_cause(sqlalchemy_exception, exc_info)
  File "c:\program files (x86)\python37-32\lib\site-packages\sqlalchemy\util\compat.py", line 398, in raise_from_cause
    reraise(type(exception), exception, tb=exc_tb, cause=cause)
  File "c:\program files (x86)\python37-32\lib\site-packages\sqlalchemy\util\compat.py", line 152, in reraise
    raise value.with_traceback(tb)
  File "c:\program files (x86)\python37-32\lib\site-packages\sqlalchemy\engine\base.py", line 1249, in _execute_context
    cursor, statement, parameters, context
  File "c:\program files (x86)\python37-32\lib\site-packages\sqlalchemy\engine\default.py", line 552, in do_execute
    cursor.execute(statement, parameters)
  File "c:\program files (x86)\python37-32\lib\site-packages\pymysql\cursors.py", line 170, in execute
    result = self._query(query)
  File "c:\program files (x86)\python37-32\lib\site-packages\pymysql\cursors.py", line 328, in _query
    conn.query(q)
  File "c:\program files (x86)\python37-32\lib\site-packages\pymysql\connections.py", line 517, in query
    self._affected_rows = self._read_query_result(unbuffered=unbuffered)
  File "c:\program files (x86)\python37-32\lib\site-packages\pymysql\connections.py", line 732, in _read_query_result
    result.read()
  File "c:\program files (x86)\python37-32\lib\site-packages\pymysql\connections.py", line 1075, in read
    first_packet = self.connection._read_packet()
  File "c:\program files (x86)\python37-32\lib\site-packages\pymysql\connections.py", line 684, in _read_packet
    packet.check_error()
  File "c:\program files (x86)\python37-32\lib\site-packages\pymysql\protocol.py", line 220, in check_error
    err.raise_mysql_exception(self._data)
  File "c:\program files (x86)\python37-32\lib\site-packages\pymysql\err.py", line 109, in raise_mysql_exception
    raise errorclass(errno, errval)
sqlalchemy.exc.ProgrammingError: (pymysql.err.ProgrammingError) (1146, "Table 'epl_predictor.prediction_view' doesn't exist")
[SQL: SELECT prediction_view.id AS prediction_view_id, prediction_view.home_team AS prediction_view_home_team, prediction_view.away_team AS prediction_view_away_team, prediction_view.winner AS prediction_view_winner, prediction_view.prediction_date AS prediction_view_prediction_date, prediction_view.username AS prediction_view_username, prediction_view.user_id AS prediction_view_user_id 
FROM prediction_view 
WHERE prediction_view.user_id = %(user_id_1)s ORDER BY prediction_view.prediction_date DESC 
 LIMIT %(param_1)s, %(param_2)s]
[parameters: {'user_id_1': 1, 'param_1': 0, 'param_2': 10}]
(Background on this error at: http://sqlalche.me/e/f405)
